Workbook

Sheet Summary
A1: BrightSide Carwash - Combined Codebase Audit
A2: Audit date | B2: 2026-09-30
A3: Repositories | B3: BrightSideCarwash-AdminDashboard-frontend, BrightSideCarwash-backend, BrightSideCarwash-website-frontend
A4: Scope | B4: Entire repositories; static code review only (no runtime testing)
A5: Total findings | B5: =COUNTA('Audit Report'!$B$2:$B$146)
A6: Quick Wins | B6: =COUNTIF('Audit Report'!$M$2:$M$146,"Yes")
A8: By Repository
A9: Repository | B9: Count
A10: BrightSideCarwash-AdminDashboard-frontend | B10: =COUNTIF('Audit Report'!$A$2:$A$146,A10)
A11: BrightSideCarwash-backend | B11: =COUNTIF('Audit Report'!$A$2:$A$146,A11)
A12: BrightSideCarwash-website-frontend | B12: =COUNTIF('Audit Report'!$A$2:$A$146,A12)
A14: By Severity
A15: Severity | B15: Count
A16: Critical | B16: =COUNTIF('Audit Report'!$I$2:$I$146,A16)
A17: High | B17: =COUNTIF('Audit Report'!$I$2:$I$146,A17)
A18: Medium | B18: =COUNTIF('Audit Report'!$I$2:$I$146,A18)
A19: Low | B19: =COUNTIF('Audit Report'!$I$2:$I$146,A19)
A21: By Priority
A22: Priority | B22: Count
A23: Critical | B23: =COUNTIF('Audit Report'!$J$2:$J$146,A23)
A24: High | B24: =COUNTIF('Audit Report'!$J$2:$J$146,A24)
A25: Medium | B25: =COUNTIF('Audit Report'!$J$2:$J$146,A25)
A26: Low | B26: =COUNTIF('Audit Report'!$J$2:$J$146,A26)
A28: By T-Shirt Size
A29: T-Shirt Size | B29: Count
A30: S | B30: =COUNTIF('Audit Report'!$L$2:$L$146,A30)
A31: M | B31: =COUNTIF('Audit Report'!$L$2:$L$146,A31)
A32: L | B32: =COUNTIF('Audit Report'!$L$2:$L$146,A32)
A33: XL | B33: =COUNTIF('Audit Report'!$L$2:$L$146,A33)
A34: XXL | B34: =COUNTIF('Audit Report'!$L$2:$L$146,A34)
A36: By Finding Type
A37: Finding Type | B37: Count
A38: Vulnerability | B38: =COUNTIF('Audit Report'!$E$2:$E$146,A38)
A39: Defect | B39: =COUNTIF('Audit Report'!$E$2:$E$146,A39)
A40: Risk | B40: =COUNTIF('Audit Report'!$E$2:$E$146,A40)
A41: Tech Debt | B41: =COUNTIF('Audit Report'!$E$2:$E$146,A41)
A42: Improvement | B42: =COUNTIF('Audit Report'!$E$2:$E$146,A42)
A44: By Confidence
A45: Confidence | B45: Count
A46: High | B46: =COUNTIF('Audit Report'!$K$2:$K$146,A46)
...

Sheet Audit Report
A1: Repository | B1: ID | C1: Category | D1: Subcategory | E1: Finding Type | F1: Issue | G1: Description | H1: Evidence | I1: Severity | J1: Priority | K1: Confidence | L1: T-Shirt Size | M1: Quick Win | N1: Affected Module | O1: File | P1: Line | Q1: Other Locations | R1: Occurrences | S1: Impact | T1: Recommendation | U1: Verification Steps | V1: Reference | W1: Dependencies | X1: Fix Status
A2: BrightSideCarwash-backend | B2: AUTH-001 | C2: Authentication & Authorization | D2: Missing Authentication (broken access control) | E2: Vulnerability | F2: All Django "admin" APIs are unauthenticated (permission_classes = []) | G2: Every view documented as "Admin ... protected by JWT" overrides DRF permissions with an empty list, and REST_FRAMEWORK sets DEFAULT_AUTHENTICATION_CLASSES=() and DEFAULT_PERMISSION_CLASSES=AllowAny. IsAdminJWTUser is imported but never applied. The admin login/refresh routes (apps/adminpanel/urls.py) are not even mounted in config/urls.py, so no admin token can be obtained and the endpoints were evidently left open. The existing unit test test_kb_endpoints_do_not_require_admin_auth asserts this open behaviour. Anyone on the internet can list customers (names, emails), read full chat transcripts by session id, upload/delete knowledge-base files, trigger the website scrape + embedding job, and create/edit/delete campaigns. | H2: class KnowledgeUploadView(APIView): permission_classes = [] | I2: Critical | J2: Critical | K2: High | L2: M | M2: Yes | N2: django-app: Knowledge Base | O2: apps/django-app/apps/knowledgebase/views.py | P2: 29-30 | Q2: apps/django-app/apps/knowledgebase/views.py:52 apps/django-app/apps/knowledgebase/views.py:67 apps/django-app/apps/knowledgebase/views.py:92 apps/django-app/apps/knowledgebase/views.py:105 apps/django-app/apps/users/views.py:20 apps/django-app/apps/users/views.py:78 apps/django-app/apps/users/views.py:98 apps/django-app/apps/sessions/views.py:46 apps/django-app/apps/campaigns/views.py:14 apps/django-app/config/settings.py:192 apps/django-app/config/urls.py:33 apps/django-app/apps/knowledgebase/tests.py:24 | R2: 10 | S2: Confidentiality: unauthenticated disclosure of customer PII and chat transcripts (privacy/legal exposure). Integrity: attacker can poison the RAG knowledge base (which feeds LLM answers shown to customers, e.g. wrong prices or malicious links), delete data, or edit campaigns. Availability/cost: unauthenticated triggers of OpenAI embedding jobs and file parsing (pypdf/docx/xls) with no size limit. Business: reputational damage; likely breach-notification duty. | T2: 1) Set REST_FRAMEWORK DEFAULT_AUTHENTICATION_CLASSES to JWTAuthentication and DEFAULT_PERMISSION_CLASSES to IsAdminJWTUser (deny by default); make the truly public views (session create, chat message) opt in explicitly with permission_classes=[AllowAny]. 2) Remove all `permission_classes = []` from admin views. 3) Mount apps.adminpanel.urls (login/refresh) in config/urls.py. 4) Rewrite the KB/users/sessions tests to assert 401/403 without a token. 5) Rotate/inspect data for tampering (KB files, campaigns) and review access logs. | U2: Without any Authorization header: `curl https://<host>/api/v1/admin/users/`, `curl https://<host>/api/v1/admin/kb/`, `curl -X DELETE https://<host>/api/v1/admin/kb/1/`, `curl https://<host>/api/v1/admin/sessions/<uuid>/`. Expect 401/403 after the fix (currently 200). Run `python manage.py test apps.knowledgebase` after updating tests. | V2: CWE-306, CWE-862; OWASP Top 10 2021 A01; OWASP API Top 10 2023 API2/API5 | X2: Open
A3: BrightSideCarwash-backend | B3: AUTH-002 | C3: Authentication & Authorization | D3: Missing Authentication (public dev endpoints) | E3: Vulnerability | F3: Unauthenticated endpoint creates bookable services in the live Square catalog | G3: POST /api/appointments/services (marked "Just for testing, not needed in a production application") has no guard and no permission metadata; the global OptionalJwtGuard lets anonymous callers through. It upserts an APPOINTMENTS_SERVICE catalog item with caller-chosen name, price and duration, bookable at all locations and assigned to a hard-coded real team member id. Because checkout charges whatever price Square holds for the variation, an attacker can create a 1-cent service, then book and pay for it, occupying real slots and polluting the production catalog. POST /api/appointments/test-confirmation-email is a second unauthenticated test endpoint that sends mail from the business address to the configured system mailbox on demand. | H3: @Post('services') @HttpCode(HttpStatus.CREATED) async createNewService(@Body() dto: CreateBookableServiceDto) { const service = await this.bookingService.createBookableService( | I3: High | J3: Critical | K3: High | L3: S | M3: Yes | N3: nest-app: Booking & Payments (Square) | O3: apps/nest-app/src/modules/application/booking/square-booking.controller.ts | P3: 26-29 | Q3: apps/nest-app/src/modules/application/booking/square-booking.controller.ts:176 apps/nest-app/src/modules/application/booking/squareup-booking.service.ts:88 | R3: 3 | S3: Business integrity: production Square catalog can be modified by anyone; enables mispriced bookings and slot hoarding; support/clean-up cost. Email endpoint is a mail-abuse/noise vector. Priority is Critical (above severity) because the route is public, trivially exploitable and the fix is a one-line removal. | T3: Delete both endpoints from the production build (or guard with JwtAuthGuard + PermissionGuard + @RequirePermission and env flag). Move catalog administration into Square Dashboard/admin tooling. Also consider a global default-deny guard (see AUTH "fail-open authorization model"). | U3: `curl -X POST https://<host>/api/appointments/services -H "Content-Type: application/json" -d '{"name":"x","priceCents":1,"durationMinutes":30,"description":"x"}'` returns 201 with a catalogItemId/serviceVariationId. After the fix expect 401/404. | V3: CWE-306; OWASP API Top 10 2023 API5 (Broken Function Level Authorization) | X3: Open
A4: BrightSideCarwash-backend | B4: AUTH-003 | C4: Authentication & Authorization | D4: Token Lifetime (JWT never effectively expires) | E4: Defect | F4: JWT expiresIn receives an absolute epoch timestamp, so tokens live ~57 years | G4: DateHelper.generateFutureDate() returns `unixSeconds` = an absolute epoch second (Math.floor((Date.now()+duration)/1000), about 1.79 billion in 2026). AuthService passes that value as `expiresIn`, which jsonwebtoken interprets as a duration in seconds added to iat. The intended 15 minute access token (7d default) and 7 day refresh token therefore expire roughly 57 years from issue. The only remaining revocation control is the Redis session blacklist. The same mistake is repeated in the refresh flow. | H4: const accessToken = this.jwtService.sign(accessTokenPayload, { expiresIn: DateHelper.generateFutureDate(appConfig().jwt.access_token_expiry || '7d').unixSeconds, secret: appConfig().jwt.access_token_secret }); const refreshToken = this.jwtService.sign(refreshTokenPayload, { expiresIn: DateHelper.generateFutureDate(appConfig().jwt.refresh_token_expiry || '30d').unixSeconds, secret: appConfig().jwt.refresh_token_secret }); | I4: High | J4: Critical | K4: High | L4: S | M4: Yes | N4: nest-app: Auth & RBAC | O4: apps/nest-app/src/modules/auth/auth.service.ts | P4: 422-423 | Q4: apps/nest-app/src/modules/auth/auth.service.ts:498 apps/nest-app/src/modules/auth/auth.service.ts:501 apps/nest-app/src/common/helper/date.helper.ts:185 | R4: 4 | S4: Any leaked access or refresh token (logs, browser storage, shared device, departed employee) gives multi-decade access to admin APIs including lead/payment data. Compounds the log-header leakage finding and makes password changes ineffective (sessions not revoked). Reported as High severity; priority is Critical because it affects every login and the fix is small. | T4: Pass the duration string directly: `expiresIn: appConfig().jwt.access_token_expiry` ('15m') and `refresh_token_expiry` ('7d'), or compute `Math.floor(ms/1000)` durations. Fix date.helper naming/usage, add a unit test asserting exp-iat, and force re-login (rotate JWT secrets) after deploying to invalidate the long-lived tokens already issued. | U4: Log in via POST /api/auth/login, base64-decode the access token payload and compare `exp - iat` (currently ~1.79e9 seconds instead of 900). After the fix it must equal the configured lifetime. | V4: CWE-613 (Insufficient Session Expiration); OWASP API Top 10 2023 API2 | X4: Open
A5: BrightSideCarwash-backend | B5: SEC-001 | C5: Security | D5: Unrestricted File Upload | E5: Vulnerability | F5: Unauthenticated test endpoint writes arbitrary files into the public static directory | G5: POST /api/test-file-upload accepts any multipart file (memoryStorage, no fileFilter, no size limit, no auth) and AppService.test() stores it via SojebStorage.put(image.originalname, buffer). With FILE_STORAGE=local the file lands under ./public/storage, which main.ts serves publicly at /storage with Cross-Origin-Resource-Policy cross-origin. Attackers can host HTML/JS/SVG on the API origin (stored XSS, phishing on the brand domain), fill the disk, or exhaust memory with very large uploads. | H5: @Post('test-file-upload') @UseInterceptors( FileInterceptor('image', { storage: multer.memoryStorage() as any }), ) @ApiExcludeEndpoint() | I5: High | J5: Critical | K5: High | L5: S | M5: Yes | N5: nest-app: Public APIs & app shell | O5: apps/nest-app/src/app.controller.ts | P5: 78-82 | Q5: apps/nest-app/src/app.service.ts:73 apps/nest-app/src/main.ts:89 | R5: 3 | S5: Public content injection on the production API domain, denial of service (disk/memory), potential malware hosting. Priority Critical because it is anonymous, trivial and a pure removal fix. | T5: Delete AppController test routes (test-file-upload, test-file-stream, test-chunk-stream) and AppService.test(). Serve uploaded content from a separate cookie-less domain/bucket with forced Content-Type and `Content-Disposition`. | U5: `curl -F image=@poc.html https://<host>/api/test-file-upload` then `curl https://<host>/storage/poc.html` returns the uploaded HTML. | V5: CWE-434, CWE-79; OWASP API Top 10 2023 API8 | X5: Open
A6: BrightSideCarwash-AdminDashboard-frontend | B6: AUTH-001 | C6: Authentication & Authorization | D6: Missing route/permission mapping | E6: Vulnerability | F6: Several admin routes have no permission requirement (AI Chatbox, Queries, Templates, Notifications) | G6: PermissionGuard allows any authenticated user through when a route matches neither ROUTE_PERMISSIONS nor a NAVIGATION_CONFIG item with a permission. The nav entries for Queries and all three AI Chatbox pages (chats, knowledge base upload/delete, AI campaigns) carry no permission field; /templates and /notifications are not in the nav config at all. Any invited staff member with an empty role therefore sees and can drive these screens (e.g. delete knowledge-base files, edit AI campaigns, change quote status) unless the backend independently enforces RBAC, which cannot be verified from this repo. | H6: // navigation.config.ts { id: "marketing-queries", label: "Queries", href: "/marketing/queries" }, // no permission { id: "ai-chatbox-knowledge", href: "/ai-chatbox/knowledge" }, // no permission // PermissionGuard.tsx:226 if (!requiredPermission) { return <>{children}</>; } | I6: High | J6: High | K6: Medium | L6: M | M6: Yes | N6: RBAC UI | O6: src/configs/navigation.config.ts | P6: 56-61 | Q6: src/configs/navigation.config.ts:134-157 (ai-chatbox items); src/components/shared/PermissionGuard.tsx:225-228 (default-allow); src/app/(admin)/templates/page.tsx; src/app/(admin)/notifications/page.tsx; src/lib/permissions.ts (no quote/ai/knowledge permissions defined) | R6: 6 | S6: Privilege boundary for the AI assistant, knowledge base and customer quote requests depends entirely on the unseen backend. Default-allow guard means any newly added route is unprotected by default. Confidence Medium because server-side enforcement is not visible. | T6: Make the guard default-deny: every route must be registered with a permission (fail closed and log unmapped routes). Add permissions such as quote:read/update, ai-chat:*, knowledge:*, ai-campaign:* to permissions.ts and attach them to the nav items and ROUTE_PERMISSIONS. Confirm the backend/AI service enforces the same checks. | U6: Log in as a user whose role has no permissions; navigate directly to /marketing/queries, /ai-chatbox/knowledge, /ai-chatbox/campaigns, /templates, /notifications: pages render. Then attempt the mutations and inspect whether the API rejects them. | V6: CWE-862, CWE-284; OWASP A01:2021; OWASP API Top 10 API5:2023 | W6: AUTH-002 | X6: Open
A7: BrightSideCarwash-AdminDashboard-frontend | B7: BUG-001 | C7: Bug / Correctness | D7: Token refresh bypass / inconsistent HTTP layer | E7: Defect | F7: Most API calls use raw fetch and bypass the 401 refresh interceptor | G7: Silent token refresh only exists in the axios interceptor. About 59 fetch() calls across 39 files (leads, gallery, news, testimonials, teams, campaigns, templates, email, stage, exports, hero, FAQ, lead detail) attach the token by hand and never refresh or retry. When the access token expires (README says 15 minutes) these calls fail with 401 and surface as generic errors until a page reload happens to trigger an axios call. When no cookie exists the header is literally 'Bearer null'. The README-described proactive refresh hook (hooks/useTokenRefresh.ts) does not exist. Cookie lifetime of 7 days means proxy.ts and isAuthenticated stay 'true' with a dead JWT. | H7: const token = getAccessToken(); const res = await fetch(`${process.env.NEXT_PUBLIC_API_BASE_URL}${url}`, { ...options, headers: { Authorization: `Bearer ${token}`, ... | I7: High | J7: High | K7: Medium | L7: L | M7: No | N7: Data access layer | O7: src/services/leads.api.ts | P7: 54-68 | Q7: Duplicated fetchFromBackend: gallery.api.ts:6, faq.api.ts:12, businessHours.api.ts:6, news.api.ts:8, testimonial.api.ts:14, category.api.ts:8, hero.api.ts:24, stage.service.ts:20, lead-detail.service.ts:7; inline fetch: team.api.ts:125, campaign.api.ts:150, template.api.ts:104, email-list.api.ts:36, useExportCSV.ts:19, useExportExcel.ts:38, AddMemberModal.tsx:17, CreateRoleModal.tsx:39, LeadDetailContent.tsx:147, and others (59 fetch( calls total; grep 'fetch(' src) | R7: 59 | S7: Core features (leads, CMS, teams, campaigns) intermittently fail after token expiry with confusing errors, forcing manual reload/re-login; refresh behaviour differs by screen. Confidence Medium because actual JWT lifetime is a backend property (README states 15 min). | T7: Route all HTTP through one client (axiosInstance or a single fetch wrapper with the same refresh/queue logic and Authorization handling), and delete the ~10 copies of fetchFromBackend. Use RTK Query fetchBaseQuery with a re-auth wrapper (baseQueryWithReauth) instead of baseQuery: async () => ({data:null}). Don't send the header when no token is present. | U7: Set a short-lived access token (or delete accessToken cookie value / use an expired JWT), open /leads: request /admin/lead returns 401 and no /auth/refresh-tokens call is made. Repeat on a page using axiosInstance (e.g. /marketing/queries) and observe the refresh happen. | V7: CWE-613; OWASP ASVS 3.3 | W7: ARCH-001 | X7: Open
A8: BrightSideCarwash-AdminDashboard-frontend | B8: SEC-001 | C8: Security | D8: Token Storage (JS-readable cookies) | E8: Vulnerability | F8: Access and refresh tokens stored in JavaScript-readable cookies | G8: Both the access token and the 7-day refresh token are written with document.cookie, so they are readable by any script running on the origin (XSS, malicious npm dependency, browser extension). The README claims 'httpOnly cookies', which is not what the code does. Cookie max-age for the access token is also 7 days (auth.config.ts) regardless of the JWT's real lifetime. The refresh token is sent in a JSON body to /auth/refresh-tokens, so the backend contract is also token-in-JS. | H8: document.cookie = `${name}=${encodeURIComponent(value)}; path=/; max-age=${maxAgeSeconds}; SameSite=Lax; secure`; // AUTH_CONFIG: ACCESS_TOKEN_MAX_AGE: 7*24*60*60, REFRESH_TOKEN_MAX_AGE: 7*24*60*60 | I8: High | J8: High | K8: High | L8: L | M8: No | N8: Auth & Session | O8: src/lib/auth-client.ts | P8: 5-8 | Q8: src/lib/auth-client.ts:15-19 (getCookie); src/configs/auth.config.ts:7-8; src/context/SocketContext.tsx:32-40 (second cookie reader); src/lib/axios-instance.ts:72 (getRefreshToken); README.md:20 | R8: 5 | S8: Any XSS or compromised third-party script can steal a long-lived refresh token and take over an admin account (lead PII, payments, team/role management, website CMS, mass email). Priority High rather than Critical because no confirmed XSS sink was found (see SEC-002). | T8: Have the backend set access/refresh tokens as HttpOnly; Secure; SameSite=Strict cookies (or use a Next.js route-handler/BFF that proxies API calls and holds tokens server-side). Remove getCookie/setTokens from client code, use credentials:'include', and shorten client-side cookie lifetimes. Until then, add a strict CSP (SEC-003) to reduce XSS blast radius. | U8: Log in, open DevTools > Application > Cookies: accessToken/refreshToken lack the HttpOnly flag; run document.cookie in the console and observe both tokens. After fix, document.cookie must not list them. | V8: CWE-922, CWE-1004; OWASP A02:2021/A07:2021; OWASP ASVS 3.4 | W8: SEC-003 | X8: Open
A9: BrightSideCarwash-backend | B9: AUTH-005 | C9: Authentication & Authorization | D9: Missing Authorization (function level) | E9: Vulnerability | F9: Admin quotes, FAQ and gallery controllers have no permission check | G9: These controllers apply JwtAuthGuard + PermissionGuard but declare no @RequirePermission, and PermissionGuard returns true when no permission metadata exists. Any authenticated account, including the seeded 'Manager' role that only holds lead:* permissions or a newly invited user with an empty role, can list, edit and delete customer quote requests (name, email, phone, vehicle) and change public site content (FAQ, gallery). | H9: @UseGuards(JwtAuthGuard, PermissionGuard) | I9: High | J9: High | K9: High | L9: M | M9: Yes | N9: nest-app: Admin CRM (leads, campaigns, email, team, roles, reports) | O9: apps/nest-app/src/modules/admin/quote/quote.controller.ts | P9: 38 | Q9: apps/nest-app/src/modules/admin/faq/faq.controller.ts:13 apps/nest-app/src/modules/admin/gallery/gallery.controller.ts:21 apps/nest-app/src/modules/auth/guards/permission.guard.ts:49 apps/nest-app/prisma/seed.ts:247 | R9: 3 | S9: Horizontal/vertical privilege issue: low-privileged staff can read and delete customer PII (quotes) and deface the marketing site. Also violates least privilege promised by the RBAC model. | T9: Add class-level @RequirePermission('quote'), ('faq'), ('gallery') (resource form maps HTTP verbs to :read/:create/:update/:delete) and seed matching permissions. Make PermissionGuard deny (or log loudly) when metadata is missing on a guarded route. | U9: Log in as manager@<seed> (lead-only permissions) and call GET /api/admin/quotes; the guard passes today (expected 403). | V9: CWE-862; OWASP API Top 10 2023 API5 | W9: AUTH-006 | X9: Open
A10: BrightSideCarwash-backend | B10: BUG-001 | C10: Bug / Correctness | D10: Money Units (cents stored as dollars) | E10: Defect | F10: Payments are stored in cents in a dollar Decimal column (amounts inflated 100x) | G10: Square amounts are integer cents. createPaymentRecord writes `amount: totalCostCents` into payments.amount, which the schema defines as Decimal(10,2) and all consumers treat as currency units: exports print `${currency} ${Number(p.amount).toFixed(2)}`, revenue KPIs sum the column. A $49.99 booking is recorded and shown as 4999.00. Lead dashboards and deposit analytics use the same column. | H10: deposit_amount: totalCostCents, | I10: High | J10: High | K10: High | L10: L | M10: No | N10: nest-app: Booking & Payments (Square) | O10: apps/nest-app/src/modules/application/booking/squareup-booking.service.ts | P10: 1234 | Q10: apps/nest-app/src/modules/admin/payment-transaction/payment-transaction.service.ts:218 apps/nest-app/src/modules/admin/report/services/deposit.analytics.service.ts:44 apps/nest-app/src/modules/admin/lead/lead.service.ts:434 apps/nest-app/prisma/schema.prisma:380 | R10: 5 | S10: Financial reporting and revenue KPIs shown to management are wrong by a factor of 100; reconciliation with Square fails. Fix requires a data migration of existing rows (size L). | T10: Convert to major units at write time (`(cents/100).toFixed(2)` via Prisma.Decimal) or store integer cents consistently and format at read time; migrate existing rows (`UPDATE payments SET amount = amount/100`) inside a reviewed migration; add a unit test using a 4999-cent fixture. | U10: Complete a sandbox booking priced $49.99 and query `SELECT amount FROM payments ORDER BY created_at DESC LIMIT 1` (returns 4999.00); GET /api/payment-transaction/export/csv shows "USD 4999.00". | V10: CWE-682 (Incorrect Calculation); Square Money docs (amounts are in smallest currency unit) | X10: Open
A11: BrightSideCarwash-backend | B11: BUG-003 | C11: Bug / Correctness | D11: Race Condition / Missing Idempotency | E11: Defect | F11: Checkout can create duplicate bookings and charges (random idempotency keys, lock not consumed) | G11: confirmBookingWithDeposit() validates the Redis lock but does not atomically consume it; the lock is deleted only after booking, payment, DB writes and email. Bookings.create and payments.create each use `idempotencyKey: randomUUID()`, so a retried or concurrent request with the same lockToken (double click, network retry, client bug) is not de-duplicated by Square. Two overlapping requests can both pass assertLockOwnership and both charge the card. | H11: const paymentResponse = await this.squareClient.payments.create({ sourceId: payload.sourceId, idempotencyKey: randomUUID(), amountMoney: { amount: BigInt(calculatedTotalCostCents), | I11: High | J11: High | K11: Medium | L11: M | M11: Yes | N11: nest-app: Booking & Payments (Square) | O11: apps/nest-app/src/modules/application/booking/squareup-booking.service.ts | P11: 776-780 | Q11: apps/nest-app/src/modules/application/booking/squareup-booking.service.ts:762 apps/nest-app/src/modules/application/booking/squareup-booking.service.ts:649 apps/nest-app/src/modules/application/booking/squareup-booking.service.ts:827 | R11: 4 | S11: Customers double charged and double booked; refunds and support effort; chargebacks. Confidence Medium because the exact Square behaviour for overlapping bookings was not exercised. | T11: Derive idempotency keys from the lockToken (e.g. `pay:${lockToken}`), atomically claim the lock first (Lua/GETDEL or SET NX "processing") and reject concurrent use, store the result under the lock for replays, and on unknown outcomes reconcile via Square before retrying. | U11: In sandbox, send two POST /appointments/checkout requests in parallel with the same lockToken and sourceId and check Square for two payments. | V11: CWE-362, CWE-799; Square idempotency docs | X11: Open
A12: BrightSideCarwash-backend | B12: CFG-001 | C12: Configuration & Environment | D12: Insecure Defaults | E12: Vulnerability | F12: Django ships insecure defaults: known SECRET_KEY, DEBUG on, any host, JWT key fallback | G12: settings.py defaults SECRET_KEY to a published string, DEBUG to True (explicit default overrides the Env(DEBUG=False) default), ALLOWED_HOSTS to ['*'], DB credentials to brightside_user/brightside_pass and MinIO credentials to minioadmin. SIMPLE_JWT SIGNING_KEY falls back to SECRET_KEY, so a deployment that forgets JWT_SECRET signs admin JWTs with the public default (forgeable). HSTS, SSL redirect, secure cookies and CSRF wildcard origins (ngrok/loca.lt) are left at dev values. .env.example itself ships DEBUG=True. | H12: SECRET_KEY = env("SECRET_KEY", default="insecure-dev-key") DEBUG = env.bool("DEBUG", default=True) ALLOWED_HOSTS = env.list("ALLOWED_HOSTS", default=["*"]) | I12: High | J12: High | K12: High | L12: S | M12: Yes | N12: django-app: Config & Service Sync | O12: apps/django-app/config/settings.py | P12: 22-24 | Q12: apps/django-app/config/settings.py:238 apps/django-app/config/settings.py:30 apps/django-app/config/settings.py:37 apps/django-app/.env.example:3 | R12: 5 | S12: DEBUG tracebacks leak settings/paths; predictable secrets allow token forgery and session tampering. Severity depends on whether production env overrides these (not verifiable from the repo). | T12: Remove defaults for SECRET_KEY/JWT_SECRET/DB creds (env() with no default fails fast), DEBUG default False, explicit ALLOWED_HOSTS, enable HSTS/secure cookies/SSL redirect, drop ngrok origins outside dev, add `manage.py check --deploy` to CI. | U12: Start the container with no .env: it boots with DEBUG=True and the default key; request a 404 to see the debug page. | V12: CWE-1188, CWE-489; Django deployment checklist | X12: Open
A13: BrightSideCarwash-backend | B13: DEP-001 | C13: Dependency Management | D13: Known Vulnerabilities (npm) | E13: Vulnerability | F13: yarn audit reports 14 critical and 452 high advisory paths in the Nest dependency tree | G13: `yarn audit --json` (yarn.lock, 1,733 packages, 60 distinct vulnerable modules; counts are per dependency path: 14 critical, 452 high, 275 moderate, 34 low) includes runtime-relevant items: @casl/ability 6.7.3 pinned (critical prototype pollution, fixed 6.7.5), multer <2.1.0 via @nestjs/platform-express (high DoS, used for every upload), jws <3.2.3 via @nestjs/jwt>jsonwebtoken (high, improper HMAC verification, used for JWT), axios <1.15.1 (high, direct), nodemailer 6.10.1 pinned (high DoS, fixed >=7.0.11), socket.io engine.io/socket.io-parser/ws chain (high DoS), @nestjs/microservices pinned 11.0.0 (high DoS, fixed 11.1.19), path-to-regexp via @nestjs/core, lodash via @nestjs/config, fast-xml-parser via @google-cloud/storage (critical), protobufjs via @googlemaps/routing (critical, unused package), basic-ftp/extract-zip via puppeteer (critical/high, unused package). Many dev-only items (@nestjs/cli, eslint, @swc/cli) have no runtime reach. | H13: "@casl/ability": "6.7.3", | I13: High | J13: High | K13: High | L13: L | M13: No | N13: Dependencies & Tests | O13: apps/nest-app/package.json | P13: 28 | Q13: apps/nest-app/package.json:71 apps/nest-app/package.json:43 apps/nest-app/package.json:54 apps/nest-app/package.json:87 apps/nest-app/package.json:45 | R13: 6 | S13: Reachability varies: multer, jws, socket.io/ws, axios and nodemailer sit on public/authenticated request paths; others are transitive or dev only. Severity follows advisory severity adjusted for reachability. audit date 2026-09-30; advisories change daily. | T13: Upgrade @casl/ability >=6.7.5, nodemailer >=7.0.11, axios >=1.15.1, align @nestjs/* to the same 11.1.x, refresh lockfile (`yarn upgrade`, resolutions for multer/jws/ws/engine.io), remove unused packages (puppeteer, firebase-admin, @googlemaps/*), re-run `yarn audit --groups dependencies` in CI. | U13: cd apps/nest-app && yarn audit --groups dependencies (read-only, needs network); verify each advisory GHSA id in the audit output. | V13: GHSA-rgwj-5xj2-c3m3 and others from yarn audit; OWASP Top 10 2021 A06 | X13: Open
A14: BrightSideCarwash-backend | B14: DEP-003 | C14: Dependency Management | D14: End-of-life Framework | E14: Vulnerability | F14: Django is capped at 5.0.x, which is out of security support | G14: requirements.txt pins Django>=5.0,<5.1. Django 5.0 is not an LTS release and stopped receiving security fixes in April 2025 (per the Django release policy), so by the audit date any 5.0.x install lacks over a year of CVE patches; the constraint also prevents upgrading to 5.1/5.2 LTS. Confidence Medium because the resolved version is unknown (no lockfile) and the EOL date is from the release policy, not the repo. | H14: Django>=5.0,<5.1 | I14: High | J14: High | K14: Medium | L14: M | M14: Yes | N14: Dependencies & Tests | O14: apps/django-app/requirements.txt | P14: 1 | Q14: apps/django-app/requirements.txt:12 | R14: 2 | S14: Unpatched framework vulnerabilities in a public-facing service. | T14: Upgrade to Django 5.2 LTS (or current supported release) and run the test suite; migrate google-generativeai to the supported google-genai SDK. | U14: `pip install -r requirements.txt && python -c "import django;print(django.VERSION)"` in a scratch venv; consult https://www.djangoproject.com/download/#supported-versions. | V14: Django supported versions policy | X14: Open
A15: BrightSideCarwash-backend | B15: OPS-002 | C15: DevOps / CI/CD / Deployment | D15: Compose (exposed data stores, weak creds) | E15: Vulnerability | F15: Compose publishes unauthenticated Redis and Postgres with weak credentials and :latest images | G15: docker-compose.yml maps Redis 6379 and Postgres 5432 to the host, Redis has no password, Postgres uses a trivial hard-coded password, and both use :latest tags. The application keeps role/permission caches, refresh tokens, session blacklists, booking locks and BullMQ queues in this Redis; PermissionGuard trusts the `role:*` keys, so write access to Redis equals privilege escalation (and can also un-revoke sessions). The `app` container also runs `yarn db:seed` at every start. | H15: image: redis:latest ports: - "6379:6379" # no requirepass configured ... image: postgres:latest / POSTGRES_PASSWORD: **** (4 chars), ports "5432:5432" | I15: High | J15: High | K15: Medium | L15: S | M15: Yes | N15: CI/CD & Containers | O15: apps/nest-app/docker-compose.yml | P15: 48 | Q15: apps/nest-app/docker-compose.yml:28 apps/nest-app/docker-compose.yml:32 apps/nest-app/src/modules/auth/guards/permission.guard.ts:82 | R15: 4 | S15: If the host firewall does not block these ports, an attacker can write role permissions to Redis or read/modify the database. Confidence Medium: depends on how production is actually deployed (CI uses pm2, not compose). | T15: Do not publish data-store ports (use the private network only), set requirepass/ACLs and TLS for Redis, source DB credentials from secrets, pin image versions, remove db:seed from the start command. | U15: From an external host: `redis-cli -h <server> -p 6379 ping`. | V15: CWE-306, CWE-1188; CIS Docker Benchmark 5.x | X15: Open
A16: BrightSideCarwash-backend | B16: OPS-005 | C16: DevOps / CI/CD / Deployment | D16: CI/CD Pipeline Defects | E16: Defect | F16: Deploy workflow ships main straight to production, ignoring the monorepo layout and without gates | G16: deploy.yml has no test, lint, build or audit stage and deploys on every push to main via a self-hosted runner. Path assumptions predate the move to apps/nest-app: the `yarn install` step runs in the checkout root (no package.json there) while later steps operate in /var/www/backend and run `git reset --hard origin/main` on the server, then `yarn install` without --frozen-lockfile, `prisma migrate deploy` before a build that may fail, and finally `pm2 stop/delete` (downtime, no rollback or health check). The Django app is not deployed by CI at all. actions/checkout@v3 is outdated and DATABASE_URL is echoed into GITHUB_ENV. | H16: - name: Install dependencies run: | yarn install | I16: High | J16: High | K16: Medium | L16: M | M16: Yes | N16: CI/CD & Containers | O16: .github/workflows/deploy.yml | P16: 25-27 | Q16: .github/workflows/deploy.yml:19 .github/workflows/deploy.yml:37 .github/workflows/deploy.yml:48 .github/workflows/deploy.yml:13 | R16: 5 | S16: Deployments may fail or run stale code; a bad commit reaches production without tests; a failed build after migration leaves DB and code out of sync. Confidence Medium: server layout (/var/www/backend) is outside the repo. | T16: Add a CI job (lint, unit tests, `yarn build`, `yarn audit --groups dependencies`, `prisma validate`) that must pass before deploy; set working-directory: apps/nest-app; use `yarn install --frozen-lockfile`; build before migrating; use `pm2 reload` plus a health check and automatic rollback; add a Django pipeline; update checkout action. | U16: Read the latest Actions run for the repo to see where `yarn install` executes; diff /var/www/backend structure against the repository. | V16: OWASP CI/CD Security Top 10 (CICD-SEC-1, -4) | X16: Open
A17: BrightSideCarwash-backend | B17: SEC-003 | C17: Security | D17: Hard-coded Default Credentials | E17: Vulnerability | F17: Seed script creates admin/manager users with hard-coded fallback passwords on every start | G17: prisma/seed.ts falls back to a well-known admin password when SYSTEM_PASSWORD is unset and always creates manager@email.com with a fixed literal password (not configurable). docker-compose runs `yarn db:seed` on every container start, and .env.example leaves the system user variables empty. Accounts are created only if missing (upsert with empty update), so any fresh environment silently ships known credentials. | H17: const adminPassword = process.env.SYSTEM_PASSWORD || 'Admi****3!'; // ... password: await hashPassword('Mana****3!'), // manager@email.com, fixed literal | I17: High | J17: High | K17: High | L17: S | M17: Yes | N17: nest-app: Auth & RBAC | O17: apps/nest-app/prisma/seed.ts | P17: 21 | Q17: apps/nest-app/prisma/seed.ts:75 apps/nest-app/docker-compose.yml:25 | R17: 3 | S17: Anyone who knows the public repo defaults can log in as Admin/Manager on any environment that did not override the variables; leads and payment data are exposed. | T17: Fail the seed when SYSTEM_PASSWORD is missing; never create a manager user with a literal password (generate a random one and print it once or require env). Remove db:seed from the container start command; run it as a one-off job. | U17: Run the seed with SYSTEM_PASSWORD unset against a scratch database and attempt to log in with the fallback credentials (do not run against production). | V17: CWE-798, CWE-1392; OWASP API Top 10 2023 API2 | X17: Open
A18: BrightSideCarwash-website-frontend | B18: API-001 | C18: API Design | D18: Idempotency | E18: Risk | F18: Checkout POST has no idempotency key; ambiguous failures can double-charge | G18: checkoutBooking() posts the Square card token and booking to /appointments/checkout with no idempotency key and no client timeout. useCheckout treats any thrown error (including network timeout after the server already charged) as 'Payment failed', and CheckoutStep then releases the lock, re-locks the slot and re-enables the Pay button. A user retrying tokenizes a fresh card nonce, so the backend cannot de-duplicate on the nonce. Whether the backend de-duplicates by lockToken/cart is not visible from this repo. | H18: const { data } = await axios.post(`${API_BASE}/appointments/checkout`, params); // CheckoutStep: else { if (lockToken) await release(...); await lock(...); } | I18: High | J18: High | K18: Medium | L18: M | M18: Yes | N18: Booking & Checkout | O18: src/services/booking.api.ts | P18: 63 | Q18: src/components/pages/booking/CheckoutStep.tsx:127-141, 162-167; src/hooks/useCheckout.ts:24-35 | R18: 3 | S18: A customer whose request times out after a successful charge may pay twice or hold a duplicate appointment. Direct financial and reputational impact on a payment path. | T18: Generate a per-attempt idempotency key (e.g. uuid stored with the cart/lock) and send it as an Idempotency-Key header; have the backend de-duplicate on it. On timeout/5xx, show 'confirming your booking' and poll a booking-status endpoint instead of re-locking and re-enabling payment. Set an axios timeout. | U18: Throttle network in DevTools, submit checkout, abort the response after the server processes it, click Pay again and observe a second charge/appointment. After fix, the second attempt with the same key must return the original result. | V18: OWASP API4:2023; CWE-841 (improper enforcement of behavioral workflow) | W18: ERR-001 | X18: Open
A19: BrightSideCarwash-backend | B19: ERR-001 | C19: Error Handling & Resilience | D19: Swallowed Exception (payment records) | E19: Defect | F19: Payment DB record failures and booking rollback failures are swallowed | G19: createPaymentRecord() catches every error and only logs it, so a successful Square charge can complete without a payments row (revenue and lead conversion tracking silently lose it) and the API still reports success. In the failure path the auto-cancel of a booking created before a declined payment is wrapped in an empty catch, leaving an orphan booking that blocks the slot; the same block then writes a 'TXN-FAIL' pseudo transaction id as if it were a real payment reference. | H19: this.logger.error('Failed to create payment record for lead:', err); | I19: Medium | J19: High | K19: High | L19: M | M19: No | N19: nest-app: Booking & Payments (Square) | O19: apps/nest-app/src/modules/application/booking/squareup-booking.service.ts | P19: 1342 | Q19: apps/nest-app/src/modules/application/booking/squareup-booking.service.ts:868 apps/nest-app/src/modules/application/booking/squareup-booking.service.ts:872 | R19: 3 | S19: Untracked money movements, orphan bookings, and unreconciled data; no alerting because errors are only logged. Priority High as it sits on the payment path. | T19: Persist an outbox/pending payment row before charging, update it after, alert (Sentry/pager) on any persistence or rollback failure, and add a reconciliation job against Square Payments API. | U19: Simulate a DB outage after payments.create in a sandbox test and observe HTTP 200 with no payments row. | V19: CWE-391 (Unchecked Error Condition) | W19: BUG-003 | X19: Open
A20: BrightSideCarwash-backend | B20: OBS-001 | C20: Logging & Monitoring | D20: Secrets in Logs | E20: Risk | F20: pino-http logs full request headers (Authorization, Cookie) with no redaction | G20: loggerConfig passes pinoHttp options with only level and transport; there is no redact list and no custom req serializer. pino-http's default request serializer includes request headers, so every request line written to stdout and to the daily log file (mounted at ./logs in docker-compose) contains the Bearer access token and refresh_token cookie. Combined with the non-expiring JWT bug this makes the log store a long-lived credential vault. | H20: pinoHttp: { level: 'info', transport: { | I20: Medium | J20: High | K20: Medium | L20: S | M20: No | N20: nest-app: Platform (config, storage, mail, notifications, logging, Prisma) | O20: apps/nest-app/src/logger.config.ts | P20: 18-20 | Q20: apps/nest-app/docker-compose.yml:15 | R20: 2 | S20: Credential disclosure to anyone with log access (support, log shippers). Confidence Medium: default serializer behaviour was not runtime-verified. Priority is High (above Medium severity) because tokens do not expire (see JWT finding), which turns any log access into persistent account access. | T20: Add `redact: { paths: ['req.headers.authorization','req.headers.cookie','res.headers["set-cookie"]'], censor: '[REDACTED]' }` and log request ids only; rotate/limit log retention. | U20: Start the app, call any authenticated endpoint and inspect the log line for req.headers.authorization. | V20: CWE-532; OWASP Logging Cheat Sheet | W20: AUTH-003 | X20: Open
A21: BrightSideCarwash-backend | B21: SEC-002 | C21: Security | D21: Unverified Webhook | E21: Vulnerability | F21: Brevo webhook accepts unauthenticated, unsigned events and stores raw payloads | G21: POST /api/webhooks/brevo has no guard, shared secret, IP allow-list or signature check. Anyone can forge delivery events (delivered/bounced/complaint) for any recipient and campaign id, flip DeliveryLog/EmailLog states, force campaigns to COMPLETED/FAILED via evaluateCampaignStatus, and persist arbitrary JSON into DeliveryLog.metaData. The full payload (recipient emails) is logged at debug level. | H21: @Post('brevo') @HttpCode(HttpStatus.OK) // Always return a 200 OK immediately to stop Brevo retry workers async handleBrevoWebhook(@Body() payload: any) { this.logger.debug(`Received Brevo Event Payload Data: ${JSON.stringify(payload)}`); | I21: Medium | J21: High | K21: High | L21: M | M21: No | N21: nest-app: Admin CRM (leads, campaigns, email, team, roles, reports) | O21: apps/nest-app/src/modules/admin/campaign/controllers/webhook.controller.ts | P21: 153-156 | Q21: apps/nest-app/src/modules/admin/campaign/controllers/webhook.controller.ts:108 apps/nest-app/src/modules/admin/campaign/controllers/webhook.controller.ts:156 | R21: 3 | S21: Corrupted campaign reporting/email status, hidden bounces (leading to re-mailing suppressed addresses), and unbounded JSON writes. Public exposure raises priority to High. | T21: Protect the webhook with a secret in the URL/header configured in Brevo (Brevo supports custom headers/basic auth) verified with timingSafeEqual, restrict to Brevo IPs at the proxy, validate the payload with a DTO/zod schema, and stop persisting the raw body. | U21: `curl -X POST https://<host>/api/webhooks/brevo -H "Content-Type: application/json" -d '{"event":"hard_bounce","email":"victim@example.com"}'` returns processed:true for any known recipient/log. | V21: CWE-345, CWE-306; OWASP API Top 10 2023 API2/API10 | X21: Open
A22: BrightSideCarwash-backend | B22: SEC-012 | C22: Security | D22: Missing Rate Limiting / Resource Abuse | E22: Risk | F22: Public chat endpoint has no throttling, message size cap or history cap | G22: POST /api/v1/chat/ is anonymous (a session is created by supplying any email) and each message triggers an LLM classifier call, an embedding call, a vector search and a completion call. REST_FRAMEWORK defines no throttle classes anywhere, `message` is a CharField without max_length, and the complete JSONB history is re-sent to OpenAI on every turn and returned to the client. One client can burn OpenAI budget and exhaust the 3 sync gunicorn workers. | H22: message = serializers.CharField(allow_blank=False, trim_whitespace=True) | I22: Medium | J22: High | K22: High | L22: M | M22: No | N22: django-app: Chatbot & Sessions | O22: apps/django-app/apps/chatbot/serializers.py | P22: 6 | Q22: apps/django-app/apps/chatbot/views.py:14 apps/django-app/apps/sessions/views.py:24 apps/django-app/config/settings.py:197 | R22: 4 | S22: Denial of wallet and denial of service on the chatbot; priority High because it is public and directly costs money. | T22: Add DRF throttling (AnonRateThrottle + per-session scoped throttle), max_length (e.g. 1000) on message/name, truncate history to the last N turns/tokens, cap messages per session, and add an OpenAI spend limit. | U22: Loop 200 POST /api/v1/chat/ requests with a valid session id and observe no 429 and rising OpenAI usage. | V22: CWE-770; OWASP API Top 10 2023 API4 | W22: AUTH-001 | X22: Open
A23: BrightSideCarwash-website-frontend | B23: TEST-001 | C23: Testing | D23: No Automated Tests | E23: Risk | F23: No automated tests for booking, payment, locking or chat flows | G23: Searched the tracked files for test/spec/__tests__/e2e/jest/vitest/playwright/cypress: no test files, no test framework in devDependencies and no test script. The slot-locking, checkout and timezone logic (the revenue-critical paths) have no regression protection. Severity Medium, Priority High because the flow handles real card payments and the code already shows date/lock defects. | H23: "scripts": { "dev", "build", "start", "lint" } // no test script; 0 test files in 286 tracked files | I23: Medium | J23: High | K23: High | L23: XL | M23: No | N23: Booking & Checkout | O23: package.json | P23: 5-10 | Q23: src/hooks/useAvailableDates.ts; src/hooks/useBookingLock.ts; src/components/pages/booking/CheckoutStep.tsx | R23: 3 | S23: Regressions in booking and checkout go undetected; refactors (see ARCH-001) are risky. | T23: Add Vitest + Testing Library for hooks/utilities (date handling, lock lifecycle, validation) and Playwright happy-path E2E (mocked API, Square test nonce) for the booking flow. | U23: ls / grep for *.test.* and *.spec.*; run npm test (script missing). | V23: Testing pyramid | X23: Open
A24: BrightSideCarwash-AdminDashboard-frontend | B24: TEST-001 | C24: Testing | D24: No automated tests | E24: Risk | F24: No test framework or tests for auth, RBAC, token refresh or money-related screens | G24: package.json has no test script, test runner, or testing-library dependency and the repo contains no *.test.*/*.spec.* files (searched with git ls-files and find). Critical logic - hasPermission wildcard matching, PermissionGuard route mapping, 401 refresh queue, ChatBubble sanitiser, payment table/export, lead pipeline drag-and-drop ranking (lexorank) - is untested. | H24: "scripts": { "dev": "next dev", "build": "next build", "start": "next start", "lint": "eslint" } | I24: High | J24: Medium | K24: High | L24: XL | M24: No | N24: Cross-cutting | O24: package.json | P24: 5-10 | Q24: src/lib/permissions.ts:136-165; src/utils/lexorank.ts; src/components/shared/PermissionGuard.tsx | R24: 4 | S24: Any change to permissions, token refresh or list/pagination logic can silently break access control or core workflows. Priority Medium because it is an enabling gap, not an active defect. | T24: Adopt Vitest + Testing Library + MSW; start with unit tests for hasPermission, getRequiredPermission, sanitizeHtml, lexorank, axios refresh queue; add Playwright smoke tests for login and RBAC. | U24: git ls-files | grep -Ei 'test|spec|__tests__' returns nothing. | W24: OPS-002 | X24: Open
A25: BrightSideCarwash-backend | B25: AUTH-004 | C25: Authentication & Authorization | D25: Privilege Escalation | E25: Vulnerability | F25: Staff invite and role-assign endpoints can grant the protected "Super User" role | G25: createStaff() only checks that the requested role name exists, and changeMemberRolesByName() accepts any existing role names; assertNotSuperUser() protects only the configured super user as a *target*. Any holder of staff:invite or member:roles_update can therefore invite themselves an accomplice, or re-role an existing account, as "Super User" (which receives every permission at boot). There is no rule that a caller may only assign roles no more privileged than their own. | H25: where: { name: role } }); | I25: High | J25: Medium | K25: High | L25: M | M25: Yes | N25: nest-app: Auth & RBAC | O25: apps/nest-app/src/modules/auth/auth.service.ts | P25: 569-571 | Q25: apps/nest-app/src/modules/admin/team/team.service.ts:154 apps/nest-app/src/modules/auth/auth.controller.ts:222 | R25: 3 | S25: Delegated administrators (e.g. a manager given invite rights) can become full super users, defeating least privilege and the audit trail. Priority Medium because it needs an already-privileged permission. | T25: Reject assignment of SYSTEM_SUPER_USER_ROLE_NAME (and optionally Admin) unless the caller already holds it; compute the caller permission set and forbid granting permissions the caller lacks. Add tests for both endpoints. | U25: Log in as a user whose role has staff:invite only; POST /api/auth/invite-staff with {"role":"Super User", ...}. It currently succeeds; expected 403. | V25: CWE-269; OWASP API Top 10 2023 API5 | X25: Open
A26: BrightSideCarwash-backend | B26: AUTH-008 | C26: Authentication & Authorization | D26: Brute Force / Password Reset | E26: Vulnerability | F26: Password-reset OTP can be guessed without attempt limiting | G26: resetPasswordWithOtp() compares the submitted 6-digit OTP with the Redis value with no failed-attempt counter (the counter and lockout exist only in verifyForgotPasswordOtp, which the reset step does not require). The only brake is the global IP throttler (100 requests/min in production) against a 900,000 value space; an attacker can request fresh OTPs repeatedly (3 minute validity) and distribute guesses. The OTP is stored in Redis in clear text and compared with !== (not constant time). The verify endpoint also lets an attacker burn a victim's OTP by submitting 5 wrong codes. | H26: if (storedOtp !== otp) { throw new BadRequestException('Invalid or expired OTP'); } | I26: High | J26: Medium | K26: Medium | L26: S | M26: Yes | N26: nest-app: Auth & RBAC | O26: apps/nest-app/src/modules/auth/auth.service.ts | P26: 1010-1012 | Q26: apps/nest-app/src/modules/auth/auth.service.ts:907 apps/nest-app/src/modules/auth/auth.controller.ts:648 | R26: 3 | S26: Account takeover of any staff account (including administrators) by a determined, distributed attacker. Confidence is Medium because feasibility depends on throttler behaviour behind the proxy. Priority is Medium (below the High severity) because exploitation needs many guesses per OTP window and is limited by the IP throttler. | T26: Apply the same attempt counter/lockout in the reset step (shared key), store a hash of the OTP, compare with timingSafeEqual, invalidate on success, add per-email rate limiting on send-otp and reset endpoints, and issue a one-time reset token after successful verification instead of re-sending the OTP. | U26: Call POST /auth/forgot-password/send-otp then hammer POST /auth/forgot-password/reset-password with different otp values; no lockout occurs after 5 attempts (only global throttling applies). | V26: CWE-307, CWE-640; OWASP API Top 10 2023 API2 | X26: Open
A27: BrightSideCarwash-website-frontend | B27: CFG-002 | C27: Configuration & Environment | D27: Insecure Default | E27: Risk | F27: Square defaults to the sandbox SDK when NEXT_PUBLIC_SQUARE_ENVIRONMENT is unset | G27: isProduction is true only when NEXT_PUBLIC_SQUARE_ENVIRONMENT === 'production'; otherwise the sandbox SDK URL is loaded and sandbox test cards are advertised in the UI. The local .env does not define this variable and uses a sandbox application id (redacted sand****ooiw). A production build lacking the variable would silently run the wrong payments environment. | H27: const isProduction = SQUARE_ENV === "production"; const SQUARE_SCRIPT_URL = isProduction ? "https://web.squarecdn.com/v1/square.js" : "https://sandbox.web.squarecdn.com/v1/square.js"; | I27: High | J27: Medium | K27: Medium | L27: S | M27: Yes | N27: Booking & Checkout | O27: src/components/pages/booking/SquarePaymentForm.tsx | P27: 54-60 | R27: 1 | S27: Failed real payments (core feature) after a deploy with a missing variable. Priority is Medium because the current .env clearly targets a non-production environment and the risk is confined to release configuration. | T27: Fail the build when NEXT_PUBLIC_SQUARE_ENVIRONMENT or APP_ID are absent, and derive the environment from a required variable rather than defaulting to sandbox. | U27: Build with NODE_ENV=production but without NEXT_PUBLIC_SQUARE_ENVIRONMENT; the checkout page loads sandbox.web.squarecdn.com. | V27: 12-factor app: config; Square Web Payments SDK docs | W27: CFG-001 | X27: Open
A28: BrightSideCarwash-AdminDashboard-frontend | B28: ARCH-001 | C28: Architecture & Design | D28: RTK Query used without baseQuery | E28: Tech Debt | F28: 24 RTK Query APIs use a dummy baseQuery and hand-rolled queryFn | G28: Every createApi declares baseQuery: async () => ({ data: null }) and implements each endpoint as a queryFn with its own try/catch and error mapping. This defeats RTK Query's central baseQuery (auth, re-auth, error normalisation, timeouts) and is the reason HTTP/error handling was copy-pasted per file (BUG-001, ERR-001). Error shapes differ per file (e.g. status hard-coded to 401/500/400 in auth.endpoints). | H28: export const galleryApi = createApi({ reducerPath: 'galleryApi', baseQuery: async () => ({ data: null }), tagTypes: ['Gallery'], | I28: Medium | J28: Medium | K28: High | L28: XL | M28: No | N28: Data access layer | O28: src/services/gallery.api.ts | P28: 26-29 | Q28: 24 files under src/services (grep 'baseQuery: async'); src/services/base-query.ts (unused axiosBaseQuery helper) | R28: 24 | S28: High cost to change auth/error behaviour; inconsistent errors; every new endpoint repeats boilerplate. | T28: Create one baseQueryWithReauth (axios or fetchBaseQuery) and convert endpoints to query/mutation definitions with transformResponse/transformErrorResponse; migrate incrementally per API. | U28: grep -rn 'baseQuery: async' src/services | wc -l | V28: RTK Query docs: Customizing Queries / Re-authorization | W28: BUG-001 | X28: Open
A29: BrightSideCarwash-AdminDashboard-frontend | B29: AUTH-002 | C29: Authentication & Authorization | D29: Weak edge protection (cookie presence only) | E29: Risk | F29: proxy.ts trusts mere cookie presence and its matcher omits several routes | G29: The Next.js proxy treats any non-empty 'accessToken' cookie as authenticated - the token is not verified or even decoded - and the matcher / PROTECTED_PREFIXES list omits /teams, /templates, /marketing, /notifications, /ai-chatbox. A forged cookie value passes the edge check for the protected prefixes, and the unlisted routes are never checked at the edge. Real protection therefore relies on client-side redirect (DashboardLayout) plus the backend. Page code is still shipped to unauthenticated visitors for the unlisted routes. | H29: const accessToken = request.cookies.get("accessToken")?.value; const isAuthenticated = !!accessToken; const PROTECTED_PREFIXES = ["/dashboard","/profile","/settings","/products","/leads","/payments","/campaigns","/staffs","/website-cms","/reports","/activity-log"]; | I29: Medium | J29: Medium | K29: High | L29: S | M29: No | N29: Auth & Session | O29: src/proxy.ts | P29: 4-16 | Q29: src/proxy.ts:31-51 (matcher); src/components/shared/DashboardLayout.tsx:47-52 (client-only redirect) | R29: 3 | S29: Unauthenticated users can load the JS shell for /teams, /templates, /marketing/*, /notifications, /ai-chatbox/*; the edge layer gives a false sense of security. Data is still gated by the API, so impact is limited to information disclosure of UI/code and confusing UX. | T29: Protect the whole (admin) group by default (matcher for everything except public paths/_next/static), and at minimum decode/verify token expiry at the edge. Derive PROTECTED_PREFIXES from the route groups instead of a hand-maintained list. Remove dead prefixes (/products, /staffs, /profile). | U29: curl -I https://<host>/teams with no cookies: returns 200 instead of a redirect to /login. Set cookie accessToken=x for /leads: proxy lets it through. | V29: CWE-306, CWE-602; OWASP A01:2021 | X29: Open
A30: BrightSideCarwash-AdminDashboard-frontend | B30: BUG-002 | C30: Bug / Correctness | D30: Logout does not revoke session | E30: Defect | F30: Logout decodes JWT with atob and can fail silently, leaving server session alive | G30: logout() base64-decodes the JWT payload with atob(token.split('.')[1]). JWT segments are base64url (may contain '-' and '_' and lack padding), so atob can throw for some payloads; the exception is swallowed by useAuth.logout's catch, and only local cookies are cleared. The server session and refresh token remain valid. When the access token cookie is already missing the function returns without calling the API at all. | H30: const token = getAccessToken(); if (!token) return; const payload = JSON.parse(atob(token.split(".")[1])); const sessionId = payload.sessionId; await axiosInstance.post("/auth/logout", { sessionId }); | I30: Medium | J30: Medium | K30: Medium | L30: S | M30: No | N30: Auth & Session | O30: src/services/auth.service.ts | P30: 50-56 | Q30: src/hooks/useAuth.ts:132-143 (catch swallows, comment '// cleanup anyway') | R30: 2 | S30: Users believe they are logged out but the stolen/copied refresh token remains usable until server expiry (up to 7 days), which matters on shared workstations. | T30: Decode with a base64url-safe helper (replace -/_ and pad) inside try/catch, or let the backend derive the session from the bearer token / refresh token. Always attempt server logout with the refresh token even if the access token is missing/expired and surface failure to the user. | U30: Log in, take a token whose payload segment contains '-' or '_' (or an expired/absent access cookie), click logout; inspect Network - no /auth/logout request or exception in console, and the refresh token still works against /auth/refresh-tokens. | V30: CWE-613; OWASP ASVS 3.3.1 | X30: Open
